[2024-09-12T09:21:45.681+0000] {taskinstance.py:1979} INFO - Dependencies all met for dep_context=non-requeueable deps ti=<TaskInstance: shopeefood_crawl_and_report.load_db manual__2024-09-12T09:16:14.482870+00:00 [queued]>
[2024-09-12T09:21:45.689+0000] {taskinstance.py:1979} INFO - Dependencies all met for dep_context=requeueable deps ti=<TaskInstance: shopeefood_crawl_and_report.load_db manual__2024-09-12T09:16:14.482870+00:00 [queued]>
[2024-09-12T09:21:45.690+0000] {taskinstance.py:2193} INFO - Starting attempt 1 of 2
[2024-09-12T09:21:45.702+0000] {taskinstance.py:2217} INFO - Executing <Task(PythonOperator): load_db> on 2024-09-12 09:16:14.482870+00:00
[2024-09-12T09:21:45.707+0000] {standard_task_runner.py:60} INFO - Started process 1952 to run task
[2024-09-12T09:21:45.710+0000] {standard_task_runner.py:87} INFO - Running: ['***', 'tasks', 'run', 'shopeefood_crawl_and_report', 'load_db', 'manual__2024-09-12T09:16:14.482870+00:00', '--job-id', '36', '--raw', '--subdir', 'DAGS_FOLDER/main_dag.py', '--cfg-path', '/tmp/tmp40qvi0pd']
[2024-09-12T09:21:45.712+0000] {standard_task_runner.py:88} INFO - Job 36: Subtask load_db
[2024-09-12T09:21:45.756+0000] {task_command.py:423} INFO - Running <TaskInstance: shopeefood_crawl_and_report.load_db manual__2024-09-12T09:16:14.482870+00:00 [running]> on host cde7247848aa
[2024-09-12T09:21:45.817+0000] {taskinstance.py:2513} INFO - Exporting env vars: AIRFLOW_CTX_DAG_OWNER='***' AIRFLOW_CTX_DAG_ID='shopeefood_crawl_and_report' AIRFLOW_CTX_TASK_ID='load_db' AIRFLOW_CTX_EXECUTION_DATE='2024-09-12T09:16:14.482870+00:00' AIRFLOW_CTX_TRY_NUMBER='1' AIRFLOW_CTX_DAG_RUN_ID='manual__2024-09-12T09:16:14.482870+00:00'
[2024-09-12T09:21:45.938+0000] {taskinstance.py:2731} ERROR - Task failed with exception
Traceback (most recent call last):
  File "/home/airflow/.local/lib/python3.8/site-packages/airflow/models/taskinstance.py", line 444, in _execute_task
    result = _execute_callable(context=context, **execute_callable_kwargs)
  File "/home/airflow/.local/lib/python3.8/site-packages/airflow/models/taskinstance.py", line 414, in _execute_callable
    return execute_callable(context=context, **execute_callable_kwargs)
  File "/home/airflow/.local/lib/python3.8/site-packages/airflow/operators/python.py", line 200, in execute
    return_value = self.execute_callable()
  File "/home/airflow/.local/lib/python3.8/site-packages/airflow/operators/python.py", line 217, in execute_callable
    return self.python_callable(*self.op_args, **self.op_kwargs)
  File "/opt/airflow/dags/load/load_to_mysql.py", line 8, in load_data
    connection = hook.get_connection('my_mysql_conn')
  File "/home/airflow/.local/lib/python3.8/site-packages/airflow/hooks/base.py", line 82, in get_connection
    conn = Connection.get_connection_from_secrets(conn_id)
  File "/home/airflow/.local/lib/python3.8/site-packages/airflow/models/connection.py", line 514, in get_connection_from_secrets
    raise AirflowNotFoundException(f"The conn_id `{conn_id}` isn't defined")
airflow.exceptions.AirflowNotFoundException: The conn_id `my_mysql_conn` isn't defined
[2024-09-12T09:21:45.956+0000] {taskinstance.py:1149} INFO - Marking task as UP_FOR_RETRY. dag_id=shopeefood_crawl_and_report, task_id=load_db, execution_date=20240912T091614, start_date=20240912T092145, end_date=20240912T092145
[2024-09-12T09:21:45.967+0000] {standard_task_runner.py:107} ERROR - Failed to execute job 36 for task load_db (The conn_id `my_mysql_conn` isn't defined; 1952)
[2024-09-12T09:21:46.005+0000] {local_task_job_runner.py:234} INFO - Task exited with return code 1
[2024-09-12T09:21:46.019+0000] {taskinstance.py:3312} INFO - 0 downstream tasks scheduled from follow-on schedule check
