[2024-09-12T14:23:13.042+0000] {taskinstance.py:1979} INFO - Dependencies all met for dep_context=non-requeueable deps ti=<TaskInstance: shopeefood_crawl_and_report.crawl_list_restaurant manual__2024-09-12T14:23:12.043985+00:00 [queued]>
[2024-09-12T14:23:13.054+0000] {taskinstance.py:1979} INFO - Dependencies all met for dep_context=requeueable deps ti=<TaskInstance: shopeefood_crawl_and_report.crawl_list_restaurant manual__2024-09-12T14:23:12.043985+00:00 [queued]>
[2024-09-12T14:23:13.055+0000] {taskinstance.py:2193} INFO - Starting attempt 1 of 2
[2024-09-12T14:23:13.075+0000] {taskinstance.py:2217} INFO - Executing <Task(PythonOperator): crawl_list_restaurant> on 2024-09-12 14:23:12.043985+00:00
[2024-09-12T14:23:13.083+0000] {standard_task_runner.py:60} INFO - Started process 14793 to run task
[2024-09-12T14:23:13.087+0000] {standard_task_runner.py:87} INFO - Running: ['***', 'tasks', 'run', 'shopeefood_crawl_and_report', 'crawl_list_restaurant', 'manual__2024-09-12T14:23:12.043985+00:00', '--job-id', '96', '--raw', '--subdir', 'DAGS_FOLDER/main_dag.py', '--cfg-path', '/tmp/tmpg4s5g0__']
[2024-09-12T14:23:13.090+0000] {standard_task_runner.py:88} INFO - Job 96: Subtask crawl_list_restaurant
[2024-09-12T14:23:13.160+0000] {task_command.py:423} INFO - Running <TaskInstance: shopeefood_crawl_and_report.crawl_list_restaurant manual__2024-09-12T14:23:12.043985+00:00 [running]> on host bc7cb9c82b76
[2024-09-12T14:23:13.400+0000] {taskinstance.py:2513} INFO - Exporting env vars: AIRFLOW_CTX_DAG_OWNER='***' AIRFLOW_CTX_DAG_ID='shopeefood_crawl_and_report' AIRFLOW_CTX_TASK_ID='crawl_list_restaurant' AIRFLOW_CTX_EXECUTION_DATE='2024-09-12T14:23:12.043985+00:00' AIRFLOW_CTX_TRY_NUMBER='1' AIRFLOW_CTX_DAG_RUN_ID='manual__2024-09-12T14:23:12.043985+00:00'
[2024-09-12T14:28:26.793+0000] {logging_mixin.py:188} INFO - Lỗi khi chờ đợi sản phẩm: Message:
[2024-09-12T14:28:26.837+0000] {logging_mixin.py:188} INFO - Lỗi khi chuyển trang hoặc crawl trang: Message: no such element: Unable to locate element: {"method":"css selector","selector":"a[href="#"] .icon-paging-next"}
  (Session info: headless chrome=117.0.5938.132); For documentation on this error, please visit: https://www.selenium.dev/documentation/webdriver/troubleshooting/errors#no-such-element-exception
Stacktrace:
#0 0x558b2d6786b3 <unknown>
#1 0x558b2d34e1e7 <unknown>
#2 0x558b2d395566 <unknown>
#3 0x558b2d395651 <unknown>
#4 0x558b2d3d2a74 <unknown>
#5 0x558b2d3b70ed <unknown>
#6 0x558b2d3d0322 <unknown>
#7 0x558b2d3b6e93 <unknown>
#8 0x558b2d389934 <unknown>
#9 0x558b2d38a71e <unknown>
#10 0x558b2d63dcb8 <unknown>
#11 0x558b2d641bf0 <unknown>
#12 0x558b2d64c19c <unknown>
#13 0x558b2d642808 <unknown>
#14 0x558b2d60f27f <unknown>
#15 0x558b2d666e88 <unknown>
#16 0x558b2d667059 <unknown>
#17 0x558b2d677843 <unknown>
#18 0x7f466fcc8609 start_thread
[2024-09-12T14:28:27.040+0000] {taskinstance.py:2731} ERROR - Task failed with exception
Traceback (most recent call last):
  File "/home/airflow/.local/lib/python3.8/site-packages/airflow/models/taskinstance.py", line 444, in _execute_task
    result = _execute_callable(context=context, **execute_callable_kwargs)
  File "/home/airflow/.local/lib/python3.8/site-packages/airflow/models/taskinstance.py", line 414, in _execute_callable
    return execute_callable(context=context, **execute_callable_kwargs)
  File "/home/airflow/.local/lib/python3.8/site-packages/airflow/operators/python.py", line 200, in execute
    return_value = self.execute_callable()
  File "/home/airflow/.local/lib/python3.8/site-packages/airflow/operators/python.py", line 217, in execute_callable
    return self.python_callable(*self.op_args, **self.op_kwargs)
  File "/opt/airflow/dags/crawler/crawl_list_restaurant.py", line 55, in crawl_list_restaurant
    df.columns=['name', 'promote', 'res_url']
  File "/home/airflow/.local/lib/python3.8/site-packages/pandas/core/generic.py", line 6002, in __setattr__
    return object.__setattr__(self, name, value)
  File "pandas/_libs/properties.pyx", line 69, in pandas._libs.properties.AxisProperty.__set__
  File "/home/airflow/.local/lib/python3.8/site-packages/pandas/core/generic.py", line 730, in _set_axis
    self._mgr.set_axis(axis, labels)
  File "/home/airflow/.local/lib/python3.8/site-packages/pandas/core/internals/managers.py", line 225, in set_axis
    self._validate_set_axis(axis, new_labels)
  File "/home/airflow/.local/lib/python3.8/site-packages/pandas/core/internals/base.py", line 70, in _validate_set_axis
    raise ValueError(
ValueError: Length mismatch: Expected axis has 0 elements, new values have 3 elements
[2024-09-12T14:28:27.102+0000] {taskinstance.py:1149} INFO - Marking task as UP_FOR_RETRY. dag_id=shopeefood_crawl_and_report, task_id=crawl_list_restaurant, execution_date=20240912T142312, start_date=20240912T142313, end_date=20240912T142827
[2024-09-12T14:28:27.170+0000] {standard_task_runner.py:107} ERROR - Failed to execute job 96 for task crawl_list_restaurant (Length mismatch: Expected axis has 0 elements, new values have 3 elements; 14793)
[2024-09-12T14:28:27.221+0000] {local_task_job_runner.py:234} INFO - Task exited with return code 1
[2024-09-12T14:28:27.255+0000] {taskinstance.py:3312} INFO - 0 downstream tasks scheduled from follow-on schedule check
