[2024-09-12T06:46:36.235+0000] {taskinstance.py:1979} INFO - Dependencies all met for dep_context=non-requeueable deps ti=<TaskInstance: shopeefood_crawl_and_report.process_report manual__2024-09-12T06:46:17.614810+00:00 [queued]>
[2024-09-12T06:46:36.248+0000] {taskinstance.py:1979} INFO - Dependencies all met for dep_context=requeueable deps ti=<TaskInstance: shopeefood_crawl_and_report.process_report manual__2024-09-12T06:46:17.614810+00:00 [queued]>
[2024-09-12T06:46:36.249+0000] {taskinstance.py:2193} INFO - Starting attempt 1 of 2
[2024-09-12T06:46:36.267+0000] {taskinstance.py:2217} INFO - Executing <Task(PythonOperator): process_report> on 2024-09-12 06:46:17.614810+00:00
[2024-09-12T06:46:36.273+0000] {standard_task_runner.py:60} INFO - Started process 2702 to run task
[2024-09-12T06:46:36.276+0000] {standard_task_runner.py:87} INFO - Running: ['***', 'tasks', 'run', 'shopeefood_crawl_and_report', 'process_report', 'manual__2024-09-12T06:46:17.614810+00:00', '--job-id', '50', '--raw', '--subdir', 'DAGS_FOLDER/main_dag.py', '--cfg-path', '/tmp/tmpm5dca2rj']
[2024-09-12T06:46:36.278+0000] {standard_task_runner.py:88} INFO - Job 50: Subtask process_report
[2024-09-12T06:46:36.349+0000] {task_command.py:423} INFO - Running <TaskInstance: shopeefood_crawl_and_report.process_report manual__2024-09-12T06:46:17.614810+00:00 [running]> on host f432431e979d
[2024-09-12T06:46:36.433+0000] {taskinstance.py:2513} INFO - Exporting env vars: AIRFLOW_CTX_DAG_OWNER='***' AIRFLOW_CTX_DAG_ID='shopeefood_crawl_and_report' AIRFLOW_CTX_TASK_ID='process_report' AIRFLOW_CTX_EXECUTION_DATE='2024-09-12T06:46:17.614810+00:00' AIRFLOW_CTX_TRY_NUMBER='1' AIRFLOW_CTX_DAG_RUN_ID='manual__2024-09-12T06:46:17.614810+00:00'
[2024-09-12T06:46:36.602+0000] {taskinstance.py:2731} ERROR - Task failed with exception
Traceback (most recent call last):
  File "/home/airflow/.local/lib/python3.8/site-packages/airflow/models/taskinstance.py", line 444, in _execute_task
    result = _execute_callable(context=context, **execute_callable_kwargs)
  File "/home/airflow/.local/lib/python3.8/site-packages/airflow/models/taskinstance.py", line 414, in _execute_callable
    return execute_callable(context=context, **execute_callable_kwargs)
  File "/home/airflow/.local/lib/python3.8/site-packages/airflow/operators/python.py", line 200, in execute
    return_value = self.execute_callable()
  File "/home/airflow/.local/lib/python3.8/site-packages/airflow/operators/python.py", line 217, in execute_callable
    return self.python_callable(*self.op_args, **self.op_kwargs)
  File "/opt/airflow/dags/report/process_data.py", line 53, in process_get_report
    df[['min_cost', 'max_cost']] = df['cost_res'].apply(lambda x: pd.Series(parse_cost_range(x)))
  File "/home/airflow/.local/lib/python3.8/site-packages/pandas/core/frame.py", line 3938, in __setitem__
    self._setitem_array(key, value)
  File "/home/airflow/.local/lib/python3.8/site-packages/pandas/core/frame.py", line 3997, in _setitem_array
    self._iset_not_inplace(key, value)
  File "/home/airflow/.local/lib/python3.8/site-packages/pandas/core/frame.py", line 4016, in _iset_not_inplace
    raise ValueError("Columns must be same length as key")
ValueError: Columns must be same length as key
[2024-09-12T06:46:36.622+0000] {taskinstance.py:1149} INFO - Marking task as UP_FOR_RETRY. dag_id=shopeefood_crawl_and_report, task_id=process_report, execution_date=20240912T064617, start_date=20240912T064636, end_date=20240912T064636
[2024-09-12T06:46:36.643+0000] {standard_task_runner.py:107} ERROR - Failed to execute job 50 for task process_report (Columns must be same length as key; 2702)
[2024-09-12T06:46:36.691+0000] {local_task_job_runner.py:234} INFO - Task exited with return code 1
[2024-09-12T06:46:36.732+0000] {taskinstance.py:3312} INFO - 0 downstream tasks scheduled from follow-on schedule check
