[2024-09-12T12:48:47.285+0000] {taskinstance.py:1979} INFO - Dependencies all met for dep_context=non-requeueable deps ti=<TaskInstance: shopeefood_crawl_and_report.crawl_list_restaurant manual__2024-09-12T12:33:14.159876+00:00 [queued]>
[2024-09-12T12:48:47.307+0000] {taskinstance.py:1979} INFO - Dependencies all met for dep_context=requeueable deps ti=<TaskInstance: shopeefood_crawl_and_report.crawl_list_restaurant manual__2024-09-12T12:33:14.159876+00:00 [queued]>
[2024-09-12T12:48:47.308+0000] {taskinstance.py:2193} INFO - Starting attempt 4 of 5
[2024-09-12T12:48:47.343+0000] {taskinstance.py:2217} INFO - Executing <Task(PythonOperator): crawl_list_restaurant> on 2024-09-12 12:33:14.159876+00:00
[2024-09-12T12:48:47.353+0000] {standard_task_runner.py:60} INFO - Started process 8102 to run task
[2024-09-12T12:48:47.360+0000] {standard_task_runner.py:87} INFO - Running: ['***', 'tasks', 'run', 'shopeefood_crawl_and_report', 'crawl_list_restaurant', 'manual__2024-09-12T12:33:14.159876+00:00', '--job-id', '60', '--raw', '--subdir', 'DAGS_FOLDER/main_dag.py', '--cfg-path', '/tmp/tmpzy6tdnmj']
[2024-09-12T12:48:47.365+0000] {standard_task_runner.py:88} INFO - Job 60: Subtask crawl_list_restaurant
[2024-09-12T12:48:47.464+0000] {task_command.py:423} INFO - Running <TaskInstance: shopeefood_crawl_and_report.crawl_list_restaurant manual__2024-09-12T12:33:14.159876+00:00 [running]> on host bc7cb9c82b76
[2024-09-12T12:48:47.969+0000] {taskinstance.py:2513} INFO - Exporting env vars: AIRFLOW_CTX_DAG_OWNER='***' AIRFLOW_CTX_DAG_ID='shopeefood_crawl_and_report' AIRFLOW_CTX_TASK_ID='crawl_list_restaurant' AIRFLOW_CTX_EXECUTION_DATE='2024-09-12T12:33:14.159876+00:00' AIRFLOW_CTX_TRY_NUMBER='4' AIRFLOW_CTX_DAG_RUN_ID='manual__2024-09-12T12:33:14.159876+00:00'
[2024-09-12T12:48:57.503+0000] {local_task_job_runner.py:280} WARNING - Recorded pid 8111 does not match the current pid 8102
[2024-09-12T12:48:57.506+0000] {process_utils.py:131} INFO - Sending 15 to group 8102. PIDs of all processes in the group: [8102]
[2024-09-12T12:48:57.507+0000] {process_utils.py:86} INFO - Sending the signal 15 to group 8102
[2024-09-12T12:48:57.508+0000] {taskinstance.py:2483} ERROR - Received SIGTERM. Terminating subprocesses.
[2024-09-12T12:48:57.520+0000] {taskinstance.py:2731} ERROR - Task failed with exception
Traceback (most recent call last):
  File "/home/airflow/.local/lib/python3.8/site-packages/airflow/models/taskinstance.py", line 444, in _execute_task
    result = _execute_callable(context=context, **execute_callable_kwargs)
  File "/home/airflow/.local/lib/python3.8/site-packages/airflow/models/taskinstance.py", line 414, in _execute_callable
    return execute_callable(context=context, **execute_callable_kwargs)
  File "/home/airflow/.local/lib/python3.8/site-packages/airflow/operators/python.py", line 200, in execute
    return_value = self.execute_callable()
  File "/home/airflow/.local/lib/python3.8/site-packages/airflow/operators/python.py", line 217, in execute_callable
    return self.python_callable(*self.op_args, **self.op_kwargs)
  File "/opt/airflow/dags/crawler/crawl_list_restaurant.py", line 9, in crawl_list_restaurant
    driver = get_driver()
  File "/opt/airflow/dags/crawler/get_driver.py", line 7, in get_driver
    driver = webdriver.Remote(
  File "/home/airflow/.local/lib/python3.8/site-packages/selenium/webdriver/remote/webdriver.py", line 212, in __init__
    self.start_session(capabilities)
  File "/home/airflow/.local/lib/python3.8/site-packages/selenium/webdriver/remote/webdriver.py", line 299, in start_session
    response = self.execute(Command.NEW_SESSION, caps)["value"]
  File "/home/airflow/.local/lib/python3.8/site-packages/selenium/webdriver/remote/webdriver.py", line 352, in execute
    response = self.command_executor.execute(driver_command, params)
  File "/home/airflow/.local/lib/python3.8/site-packages/selenium/webdriver/remote/remote_connection.py", line 306, in execute
    return self._request(command_info[0], url, body=data)
  File "/home/airflow/.local/lib/python3.8/site-packages/selenium/webdriver/remote/remote_connection.py", line 326, in _request
    response = self._conn.request(method, url, body=body, headers=headers)
  File "/home/airflow/.local/lib/python3.8/site-packages/urllib3/request.py", line 81, in request
    return self.request_encode_body(
  File "/home/airflow/.local/lib/python3.8/site-packages/urllib3/request.py", line 173, in request_encode_body
    return self.urlopen(method, url, **extra_kw)
  File "/home/airflow/.local/lib/python3.8/site-packages/urllib3/poolmanager.py", line 376, in urlopen
    response = conn.urlopen(method, u.request_uri, **kw)
  File "/home/airflow/.local/lib/python3.8/site-packages/urllib3/connectionpool.py", line 715, in urlopen
    httplib_response = self._make_request(
  File "/home/airflow/.local/lib/python3.8/site-packages/urllib3/connectionpool.py", line 467, in _make_request
    six.raise_from(e, None)
  File "<string>", line 3, in raise_from
  File "/home/airflow/.local/lib/python3.8/site-packages/urllib3/connectionpool.py", line 462, in _make_request
    httplib_response = conn.getresponse()
  File "/usr/local/lib/python3.8/http/client.py", line 1348, in getresponse
    response.begin()
  File "/usr/local/lib/python3.8/http/client.py", line 316, in begin
    version, status, reason = self._read_status()
  File "/usr/local/lib/python3.8/http/client.py", line 277, in _read_status
    line = str(self.fp.readline(_MAXLINE + 1), "iso-8859-1")
  File "/usr/local/lib/python3.8/socket.py", line 669, in readinto
    return self._sock.recv_into(b)
  File "/home/airflow/.local/lib/python3.8/site-packages/airflow/models/taskinstance.py", line 2485, in signal_handler
    raise AirflowException("Task received SIGTERM signal")
airflow.exceptions.AirflowException: Task received SIGTERM signal
[2024-09-12T12:48:57.550+0000] {taskinstance.py:1149} INFO - Marking task as UP_FOR_RETRY. dag_id=shopeefood_crawl_and_report, task_id=crawl_list_restaurant, execution_date=20240912T123314, start_date=20240912T124853, end_date=20240912T124857
[2024-09-12T12:48:57.568+0000] {standard_task_runner.py:107} ERROR - Failed to execute job 60 for task crawl_list_restaurant (Task received SIGTERM signal; 8102)
[2024-09-12T12:48:57.601+0000] {process_utils.py:79} INFO - Process psutil.Process(pid=8102, status='terminated', exitcode=1, started='12:48:46') (8102) terminated with exit code 1
