[2024-09-10T19:07:57.868+0000] {taskinstance.py:1979} INFO - Dependencies all met for dep_context=non-requeueable deps ti=<TaskInstance: shopeefood_crawl_and_report.process_report manual__2024-09-10T18:54:57.252063+00:00 [queued]>
[2024-09-10T19:07:57.887+0000] {taskinstance.py:1979} INFO - Dependencies all met for dep_context=requeueable deps ti=<TaskInstance: shopeefood_crawl_and_report.process_report manual__2024-09-10T18:54:57.252063+00:00 [queued]>
[2024-09-10T19:07:57.888+0000] {taskinstance.py:2193} INFO - Starting attempt 2 of 2
[2024-09-10T19:07:57.917+0000] {taskinstance.py:2217} INFO - Executing <Task(PythonOperator): process_report> on 2024-09-10 18:54:57.252063+00:00
[2024-09-10T19:07:57.926+0000] {standard_task_runner.py:60} INFO - Started process 3155 to run task
[2024-09-10T19:07:57.931+0000] {standard_task_runner.py:87} INFO - Running: ['***', 'tasks', 'run', 'shopeefood_crawl_and_report', 'process_report', 'manual__2024-09-10T18:54:57.252063+00:00', '--job-id', '30', '--raw', '--subdir', 'DAGS_FOLDER/main_dag.py', '--cfg-path', '/tmp/tmpgwfciu0f']
[2024-09-10T19:07:57.935+0000] {standard_task_runner.py:88} INFO - Job 30: Subtask process_report
[2024-09-10T19:07:58.032+0000] {task_command.py:423} INFO - Running <TaskInstance: shopeefood_crawl_and_report.process_report manual__2024-09-10T18:54:57.252063+00:00 [running]> on host 32137a89b089
[2024-09-10T19:07:58.699+0000] {taskinstance.py:2513} INFO - Exporting env vars: AIRFLOW_CTX_DAG_OWNER='***' AIRFLOW_CTX_DAG_ID='shopeefood_crawl_and_report' AIRFLOW_CTX_TASK_ID='process_report' AIRFLOW_CTX_EXECUTION_DATE='2024-09-10T18:54:57.252063+00:00' AIRFLOW_CTX_TRY_NUMBER='2' AIRFLOW_CTX_DAG_RUN_ID='manual__2024-09-10T18:54:57.252063+00:00'
[2024-09-10T19:07:58.711+0000] {taskinstance.py:2731} ERROR - Task failed with exception
Traceback (most recent call last):
  File "/home/airflow/.local/lib/python3.8/site-packages/airflow/models/taskinstance.py", line 444, in _execute_task
    result = _execute_callable(context=context, **execute_callable_kwargs)
  File "/home/airflow/.local/lib/python3.8/site-packages/airflow/models/taskinstance.py", line 414, in _execute_callable
    return execute_callable(context=context, **execute_callable_kwargs)
  File "/home/airflow/.local/lib/python3.8/site-packages/airflow/operators/python.py", line 200, in execute
    return_value = self.execute_callable()
  File "/home/airflow/.local/lib/python3.8/site-packages/airflow/operators/python.py", line 217, in execute_callable
    return self.python_callable(*self.op_args, **self.op_kwargs)
  File "/opt/airflow/dags/report/process_data.py", line 4, in process_get_report
    df = pd.read_csv('/opt/airflow/dags/raw_restaurant_data.csv')
  File "/home/airflow/.local/lib/python3.8/site-packages/pandas/io/parsers/readers.py", line 912, in read_csv
    return _read(filepath_or_buffer, kwds)
  File "/home/airflow/.local/lib/python3.8/site-packages/pandas/io/parsers/readers.py", line 577, in _read
    parser = TextFileReader(filepath_or_buffer, **kwds)
  File "/home/airflow/.local/lib/python3.8/site-packages/pandas/io/parsers/readers.py", line 1407, in __init__
    self._engine = self._make_engine(f, self.engine)
  File "/home/airflow/.local/lib/python3.8/site-packages/pandas/io/parsers/readers.py", line 1661, in _make_engine
    self.handles = get_handle(
  File "/home/airflow/.local/lib/python3.8/site-packages/pandas/io/common.py", line 859, in get_handle
    handle = open(
FileNotFoundError: [Errno 2] No such file or directory: '/opt/airflow/dags/raw_restaurant_data.csv'
[2024-09-10T19:07:58.736+0000] {taskinstance.py:1149} INFO - Marking task as FAILED. dag_id=shopeefood_crawl_and_report, task_id=process_report, execution_date=20240910T185457, start_date=20240910T190757, end_date=20240910T190758
[2024-09-10T19:07:58.759+0000] {standard_task_runner.py:107} ERROR - Failed to execute job 30 for task process_report ([Errno 2] No such file or directory: '/opt/airflow/dags/raw_restaurant_data.csv'; 3155)
[2024-09-10T19:07:58.797+0000] {local_task_job_runner.py:234} INFO - Task exited with return code 1
[2024-09-10T19:07:58.841+0000] {taskinstance.py:3312} INFO - 0 downstream tasks scheduled from follow-on schedule check
